<?xml version="1.0"?>
<robot name="target_model">
    <link name="world"/>

    <joint name="floating_base" type="floating">
        <parent link="world"/>
        <child link="target"/>
        <origin xyz="0 0 0" rpy="0 0 0"/>
    </joint>

    <link name="target">
        <visual>
            <origin xyz="0 0 0" rpy="0 0 0"/>
            <geometry>
                <!--<mesh filename="package://test_cube/description/meshes/visual/turtle.dae"/> -->
                <mesh filename="package://franka_integ_sim/description/robot/dae/target.dae"/>
            </geometry>
           
        </visual>
        <collision>
            <origin xyz="0 0 0" rpy="0 0 0"/>
            <geometry>
                <!--<mesh filename="package://test_cube/description/meshes/collision/turtle.stl"/> -->
                <mesh filename="package://franka_integ_sim/description/robot/stl/target.stl"/> 
            </geometry>
        </collision>
        <inertial>
            <mass value="0.50"/>
            <inertia ixx="0.00333" ixy="0.0" ixz="0.0"
                     iyy="0.00333" iyz="0.0"
                     izz="0.00333"/>
        </inertial>
    </link>

    <gazebo reference="target">
        <gravity>1</gravity>  
        <self_collide>1</self_collide>
        <static>1</static>
    </gazebo>
</robot>
